ERROR:TeleBot:Infinity polling: polling exited
ERROR:TeleBot:Break infinity polling
ERROR:TeleBot:Infinity polling exception: HTTPSConnectionPool(host='api.telegram.org', port=443): Read timed out. (read timeout=25)
ERROR:TeleBot:Exception traceback:
Traceback (most recent call last):
  File "/home/tepes/PycharmProjects/testing_python/venv/lib/python3.8/site-packages/urllib3/connectionpool.py", line 449, in _make_request
    six.raise_from(e, None)
  File "<string>", line 3, in raise_from
  File "/home/tepes/PycharmProjects/testing_python/venv/lib/python3.8/site-packages/urllib3/connectionpool.py", line 444, in _make_request
    httplib_response = conn.getresponse()
  File "/usr/lib/python3.8/http/client.py", line 1348, in getresponse
    response.begin()
  File "/usr/lib/python3.8/http/client.py", line 316, in begin
    version, status, reason = self._read_status()
  File "/usr/lib/python3.8/http/client.py", line 277, in _read_status
    line = str(self.fp.readline(_MAXLINE + 1), "iso-8859-1")
  File "/usr/lib/python3.8/socket.py", line 669, in readinto
    return self._sock.recv_into(b)
  File "/usr/lib/python3.8/ssl.py", line 1241, in recv_into
    return self.read(nbytes, buffer)
  File "/usr/lib/python3.8/ssl.py", line 1099, in read
    return self._sslobj.read(len, buffer)
socket.timeout: The read operation timed out

During handling of the above exception, another exception occurred:

Traceback (most recent call last):
  File "/home/tepes/PycharmProjects/testing_python/venv/lib/python3.8/site-packages/requests/adapters.py", line 440, in send
    resp = conn.urlopen(
  File "/home/tepes/PycharmProjects/testing_python/venv/lib/python3.8/site-packages/urllib3/connectionpool.py", line 785, in urlopen
    retries = retries.increment(
  File "/home/tepes/PycharmProjects/testing_python/venv/lib/python3.8/site-packages/urllib3/util/retry.py", line 550, in increment
    raise six.reraise(type(error), error, _stacktrace)
  File "/home/tepes/PycharmProjects/testing_python/venv/lib/python3.8/site-packages/urllib3/packages/six.py", line 770, in reraise
    raise value
  File "/home/tepes/PycharmProjects/testing_python/venv/lib/python3.8/site-packages/urllib3/connectionpool.py", line 703, in urlopen
    httplib_response = self._make_request(
  File "/home/tepes/PycharmProjects/testing_python/venv/lib/python3.8/site-packages/urllib3/connectionpool.py", line 451, in _make_request
    self._raise_timeout(err=e, url=url, timeout_value=read_timeout)
  File "/home/tepes/PycharmProjects/testing_python/venv/lib/python3.8/site-packages/urllib3/connectionpool.py", line 340, in _raise_timeout
    raise ReadTimeoutError(
urllib3.exceptions.ReadTimeoutError: HTTPSConnectionPool(host='api.telegram.org', port=443): Read timed out. (read timeout=25)

During handling of the above exception, another exception occurred:

Traceback (most recent call last):
  File "/home/tepes/PycharmProjects/testing_python/venv/lib/python3.8/site-packages/telebot/__init__.py", line 581, in infinity_polling
    self.polling(none_stop=True, timeout=timeout, long_polling_timeout=long_polling_timeout,
  File "/home/tepes/PycharmProjects/testing_python/venv/lib/python3.8/site-packages/telebot/__init__.py", line 629, in polling
    self.__threaded_polling(non_stop, interval, timeout, long_polling_timeout, allowed_updates)
  File "/home/tepes/PycharmProjects/testing_python/venv/lib/python3.8/site-packages/telebot/__init__.py", line 691, in __threaded_polling
    raise e
  File "/home/tepes/PycharmProjects/testing_python/venv/lib/python3.8/site-packages/telebot/__init__.py", line 650, in __threaded_polling
    polling_thread.raise_exceptions()
  File "/home/tepes/PycharmProjects/testing_python/venv/lib/python3.8/site-packages/telebot/util.py", line 107, in raise_exceptions
    raise self.exception_info
  File "/home/tepes/PycharmProjects/testing_python/venv/lib/python3.8/site-packages/telebot/util.py", line 89, in run
    task(*args, **kwargs)
  File "/home/tepes/PycharmProjects/testing_python/venv/lib/python3.8/site-packages/telebot/__init__.py", line 371, in __retrieve_updates
    updates = self.get_updates(offset=(self.last_update_id + 1),
  File "/home/tepes/PycharmProjects/testing_python/venv/lib/python3.8/site-packages/telebot/__init__.py", line 349, in get_updates
    json_updates = apihelper.get_updates(self.token, offset, limit, timeout, allowed_updates, long_polling_timeout)
  File "/home/tepes/PycharmProjects/testing_python/venv/lib/python3.8/site-packages/telebot/apihelper.py", line 328, in get_updates
    return _make_request(token, method_url, params=payload)
  File "/home/tepes/PycharmProjects/testing_python/venv/lib/python3.8/site-packages/telebot/apihelper.py", line 152, in _make_request
    result = _get_req_session().request(
  File "/home/tepes/PycharmProjects/testing_python/venv/lib/python3.8/site-packages/requests/sessions.py", line 529, in request
    resp = self.send(prep, **send_kwargs)
  File "/home/tepes/PycharmProjects/testing_python/venv/lib/python3.8/site-packages/requests/sessions.py", line 645, in send
    r = adapter.send(request, **kwargs)
  File "/home/tepes/PycharmProjects/testing_python/venv/lib/python3.8/site-packages/requests/adapters.py", line 532, in send
    raise ReadTimeout(e, request=request)
requests.exceptions.ReadTimeout: HTTPSConnectionPool(host='api.telegram.org', port=443): Read timed out. (read timeout=25)

ERROR:TeleBot:Infinity polling exception: HTTPSConnectionPool(host='api.telegram.org', port=443): Read timed out. (read timeout=25)
ERROR:TeleBot:Exception traceback:
Traceback (most recent call last):
  File "/home/tepes/PycharmProjects/testing_python/venv/lib/python3.8/site-packages/urllib3/connectionpool.py", line 449, in _make_request
    six.raise_from(e, None)
  File "<string>", line 3, in raise_from
  File "/home/tepes/PycharmProjects/testing_python/venv/lib/python3.8/site-packages/urllib3/connectionpool.py", line 444, in _make_request
    httplib_response = conn.getresponse()
  File "/usr/lib/python3.8/http/client.py", line 1348, in getresponse
    response.begin()
  File "/usr/lib/python3.8/http/client.py", line 316, in begin
    version, status, reason = self._read_status()
  File "/usr/lib/python3.8/http/client.py", line 277, in _read_status
    line = str(self.fp.readline(_MAXLINE + 1), "iso-8859-1")
  File "/usr/lib/python3.8/socket.py", line 669, in readinto
    return self._sock.recv_into(b)
  File "/usr/lib/python3.8/ssl.py", line 1241, in recv_into
    return self.read(nbytes, buffer)
  File "/usr/lib/python3.8/ssl.py", line 1099, in read
    return self._sslobj.read(len, buffer)
socket.timeout: The read operation timed out

During handling of the above exception, another exception occurred:

Traceback (most recent call last):
  File "/home/tepes/PycharmProjects/testing_python/venv/lib/python3.8/site-packages/requests/adapters.py", line 440, in send
    resp = conn.urlopen(
  File "/home/tepes/PycharmProjects/testing_python/venv/lib/python3.8/site-packages/urllib3/connectionpool.py", line 785, in urlopen
    retries = retries.increment(
  File "/home/tepes/PycharmProjects/testing_python/venv/lib/python3.8/site-packages/urllib3/util/retry.py", line 550, in increment
    raise six.reraise(type(error), error, _stacktrace)
  File "/home/tepes/PycharmProjects/testing_python/venv/lib/python3.8/site-packages/urllib3/packages/six.py", line 770, in reraise
    raise value
  File "/home/tepes/PycharmProjects/testing_python/venv/lib/python3.8/site-packages/urllib3/connectionpool.py", line 703, in urlopen
    httplib_response = self._make_request(
  File "/home/tepes/PycharmProjects/testing_python/venv/lib/python3.8/site-packages/urllib3/connectionpool.py", line 451, in _make_request
    self._raise_timeout(err=e, url=url, timeout_value=read_timeout)
  File "/home/tepes/PycharmProjects/testing_python/venv/lib/python3.8/site-packages/urllib3/connectionpool.py", line 340, in _raise_timeout
    raise ReadTimeoutError(
urllib3.exceptions.ReadTimeoutError: HTTPSConnectionPool(host='api.telegram.org', port=443): Read timed out. (read timeout=25)

During handling of the above exception, another exception occurred:

Traceback (most recent call last):
  File "/home/tepes/PycharmProjects/testing_python/venv/lib/python3.8/site-packages/telebot/__init__.py", line 581, in infinity_polling
    self.polling(none_stop=True, timeout=timeout, long_polling_timeout=long_polling_timeout,
  File "/home/tepes/PycharmProjects/testing_python/venv/lib/python3.8/site-packages/telebot/__init__.py", line 629, in polling
    self.__threaded_polling(non_stop, interval, timeout, long_polling_timeout, allowed_updates)
  File "/home/tepes/PycharmProjects/testing_python/venv/lib/python3.8/site-packages/telebot/__init__.py", line 691, in __threaded_polling
    raise e
  File "/home/tepes/PycharmProjects/testing_python/venv/lib/python3.8/site-packages/telebot/__init__.py", line 650, in __threaded_polling
    polling_thread.raise_exceptions()
  File "/home/tepes/PycharmProjects/testing_python/venv/lib/python3.8/site-packages/telebot/util.py", line 107, in raise_exceptions
    raise self.exception_info
  File "/home/tepes/PycharmProjects/testing_python/venv/lib/python3.8/site-packages/telebot/util.py", line 89, in run
    task(*args, **kwargs)
  File "/home/tepes/PycharmProjects/testing_python/venv/lib/python3.8/site-packages/telebot/__init__.py", line 371, in __retrieve_updates
    updates = self.get_updates(offset=(self.last_update_id + 1),
  File "/home/tepes/PycharmProjects/testing_python/venv/lib/python3.8/site-packages/telebot/__init__.py", line 349, in get_updates
    json_updates = apihelper.get_updates(self.token, offset, limit, timeout, allowed_updates, long_polling_timeout)
  File "/home/tepes/PycharmProjects/testing_python/venv/lib/python3.8/site-packages/telebot/apihelper.py", line 328, in get_updates
    return _make_request(token, method_url, params=payload)
  File "/home/tepes/PycharmProjects/testing_python/venv/lib/python3.8/site-packages/telebot/apihelper.py", line 152, in _make_request
    result = _get_req_session().request(
  File "/home/tepes/PycharmProjects/testing_python/venv/lib/python3.8/site-packages/requests/sessions.py", line 529, in request
    resp = self.send(prep, **send_kwargs)
  File "/home/tepes/PycharmProjects/testing_python/venv/lib/python3.8/site-packages/requests/sessions.py", line 645, in send
    r = adapter.send(request, **kwargs)
  File "/home/tepes/PycharmProjects/testing_python/venv/lib/python3.8/site-packages/requests/adapters.py", line 532, in send
    raise ReadTimeout(e, request=request)
requests.exceptions.ReadTimeout: HTTPSConnectionPool(host='api.telegram.org', port=443): Read timed out. (read timeout=25)

ERROR:TeleBot:Infinity polling exception: HTTPSConnectionPool(host='api.telegram.org', port=443): Read timed out. (read timeout=25)
ERROR:TeleBot:Exception traceback:
Traceback (most recent call last):
  File "/home/tepes/PycharmProjects/testing_python/venv/lib/python3.8/site-packages/urllib3/connectionpool.py", line 449, in _make_request
    six.raise_from(e, None)
  File "<string>", line 3, in raise_from
  File "/home/tepes/PycharmProjects/testing_python/venv/lib/python3.8/site-packages/urllib3/connectionpool.py", line 444, in _make_request
    httplib_response = conn.getresponse()
  File "/usr/lib/python3.8/http/client.py", line 1348, in getresponse
    response.begin()
  File "/usr/lib/python3.8/http/client.py", line 316, in begin
    version, status, reason = self._read_status()
  File "/usr/lib/python3.8/http/client.py", line 277, in _read_status
    line = str(self.fp.readline(_MAXLINE + 1), "iso-8859-1")
  File "/usr/lib/python3.8/socket.py", line 669, in readinto
    return self._sock.recv_into(b)
  File "/usr/lib/python3.8/ssl.py", line 1241, in recv_into
    return self.read(nbytes, buffer)
  File "/usr/lib/python3.8/ssl.py", line 1099, in read
    return self._sslobj.read(len, buffer)
socket.timeout: The read operation timed out

During handling of the above exception, another exception occurred:

Traceback (most recent call last):
  File "/home/tepes/PycharmProjects/testing_python/venv/lib/python3.8/site-packages/requests/adapters.py", line 440, in send
    resp = conn.urlopen(
  File "/home/tepes/PycharmProjects/testing_python/venv/lib/python3.8/site-packages/urllib3/connectionpool.py", line 785, in urlopen
    retries = retries.increment(
  File "/home/tepes/PycharmProjects/testing_python/venv/lib/python3.8/site-packages/urllib3/util/retry.py", line 550, in increment
    raise six.reraise(type(error), error, _stacktrace)
  File "/home/tepes/PycharmProjects/testing_python/venv/lib/python3.8/site-packages/urllib3/packages/six.py", line 770, in reraise
    raise value
  File "/home/tepes/PycharmProjects/testing_python/venv/lib/python3.8/site-packages/urllib3/connectionpool.py", line 703, in urlopen
    httplib_response = self._make_request(
  File "/home/tepes/PycharmProjects/testing_python/venv/lib/python3.8/site-packages/urllib3/connectionpool.py", line 451, in _make_request
    self._raise_timeout(err=e, url=url, timeout_value=read_timeout)
  File "/home/tepes/PycharmProjects/testing_python/venv/lib/python3.8/site-packages/urllib3/connectionpool.py", line 340, in _raise_timeout
    raise ReadTimeoutError(
urllib3.exceptions.ReadTimeoutError: HTTPSConnectionPool(host='api.telegram.org', port=443): Read timed out. (read timeout=25)

During handling of the above exception, another exception occurred:

Traceback (most recent call last):
  File "/home/tepes/PycharmProjects/testing_python/venv/lib/python3.8/site-packages/telebot/__init__.py", line 581, in infinity_polling
    self.polling(none_stop=True, timeout=timeout, long_polling_timeout=long_polling_timeout,
  File "/home/tepes/PycharmProjects/testing_python/venv/lib/python3.8/site-packages/telebot/__init__.py", line 629, in polling
    self.__threaded_polling(non_stop, interval, timeout, long_polling_timeout, allowed_updates)
  File "/home/tepes/PycharmProjects/testing_python/venv/lib/python3.8/site-packages/telebot/__init__.py", line 691, in __threaded_polling
    raise e
  File "/home/tepes/PycharmProjects/testing_python/venv/lib/python3.8/site-packages/telebot/__init__.py", line 650, in __threaded_polling
    polling_thread.raise_exceptions()
  File "/home/tepes/PycharmProjects/testing_python/venv/lib/python3.8/site-packages/telebot/util.py", line 107, in raise_exceptions
    raise self.exception_info
  File "/home/tepes/PycharmProjects/testing_python/venv/lib/python3.8/site-packages/telebot/util.py", line 89, in run
    task(*args, **kwargs)
  File "/home/tepes/PycharmProjects/testing_python/venv/lib/python3.8/site-packages/telebot/__init__.py", line 371, in __retrieve_updates
    updates = self.get_updates(offset=(self.last_update_id + 1),
  File "/home/tepes/PycharmProjects/testing_python/venv/lib/python3.8/site-packages/telebot/__init__.py", line 349, in get_updates
    json_updates = apihelper.get_updates(self.token, offset, limit, timeout, allowed_updates, long_polling_timeout)
  File "/home/tepes/PycharmProjects/testing_python/venv/lib/python3.8/site-packages/telebot/apihelper.py", line 328, in get_updates
    return _make_request(token, method_url, params=payload)
  File "/home/tepes/PycharmProjects/testing_python/venv/lib/python3.8/site-packages/telebot/apihelper.py", line 152, in _make_request
    result = _get_req_session().request(
  File "/home/tepes/PycharmProjects/testing_python/venv/lib/python3.8/site-packages/requests/sessions.py", line 529, in request
    resp = self.send(prep, **send_kwargs)
  File "/home/tepes/PycharmProjects/testing_python/venv/lib/python3.8/site-packages/requests/sessions.py", line 645, in send
    r = adapter.send(request, **kwargs)
  File "/home/tepes/PycharmProjects/testing_python/venv/lib/python3.8/site-packages/requests/adapters.py", line 532, in send
    raise ReadTimeout(e, request=request)
requests.exceptions.ReadTimeout: HTTPSConnectionPool(host='api.telegram.org', port=443): Read timed out. (read timeout=25)

ERROR:TeleBot:Infinity polling exception: HTTPSConnectionPool(host='api.telegram.org', port=443): Read timed out. (read timeout=25)
ERROR:TeleBot:Exception traceback:
Traceback (most recent call last):
  File "/home/tepes/PycharmProjects/testing_python/venv/lib/python3.8/site-packages/urllib3/connectionpool.py", line 449, in _make_request
    six.raise_from(e, None)
  File "<string>", line 3, in raise_from
  File "/home/tepes/PycharmProjects/testing_python/venv/lib/python3.8/site-packages/urllib3/connectionpool.py", line 444, in _make_request
    httplib_response = conn.getresponse()
  File "/usr/lib/python3.8/http/client.py", line 1348, in getresponse
    response.begin()
  File "/usr/lib/python3.8/http/client.py", line 316, in begin
    version, status, reason = self._read_status()
  File "/usr/lib/python3.8/http/client.py", line 277, in _read_status
    line = str(self.fp.readline(_MAXLINE + 1), "iso-8859-1")
  File "/usr/lib/python3.8/socket.py", line 669, in readinto
    return self._sock.recv_into(b)
  File "/usr/lib/python3.8/ssl.py", line 1241, in recv_into
    return self.read(nbytes, buffer)
  File "/usr/lib/python3.8/ssl.py", line 1099, in read
    return self._sslobj.read(len, buffer)
socket.timeout: The read operation timed out

During handling of the above exception, another exception occurred:

Traceback (most recent call last):
  File "/home/tepes/PycharmProjects/testing_python/venv/lib/python3.8/site-packages/requests/adapters.py", line 440, in send
    resp = conn.urlopen(
  File "/home/tepes/PycharmProjects/testing_python/venv/lib/python3.8/site-packages/urllib3/connectionpool.py", line 785, in urlopen
    retries = retries.increment(
  File "/home/tepes/PycharmProjects/testing_python/venv/lib/python3.8/site-packages/urllib3/util/retry.py", line 550, in increment
    raise six.reraise(type(error), error, _stacktrace)
  File "/home/tepes/PycharmProjects/testing_python/venv/lib/python3.8/site-packages/urllib3/packages/six.py", line 770, in reraise
    raise value
  File "/home/tepes/PycharmProjects/testing_python/venv/lib/python3.8/site-packages/urllib3/connectionpool.py", line 703, in urlopen
    httplib_response = self._make_request(
  File "/home/tepes/PycharmProjects/testing_python/venv/lib/python3.8/site-packages/urllib3/connectionpool.py", line 451, in _make_request
    self._raise_timeout(err=e, url=url, timeout_value=read_timeout)
  File "/home/tepes/PycharmProjects/testing_python/venv/lib/python3.8/site-packages/urllib3/connectionpool.py", line 340, in _raise_timeout
    raise ReadTimeoutError(
urllib3.exceptions.ReadTimeoutError: HTTPSConnectionPool(host='api.telegram.org', port=443): Read timed out. (read timeout=25)

During handling of the above exception, another exception occurred:

Traceback (most recent call last):
  File "/home/tepes/PycharmProjects/testing_python/venv/lib/python3.8/site-packages/telebot/__init__.py", line 581, in infinity_polling
    self.polling(none_stop=True, timeout=timeout, long_polling_timeout=long_polling_timeout,
  File "/home/tepes/PycharmProjects/testing_python/venv/lib/python3.8/site-packages/telebot/__init__.py", line 629, in polling
    self.__threaded_polling(non_stop, interval, timeout, long_polling_timeout, allowed_updates)
  File "/home/tepes/PycharmProjects/testing_python/venv/lib/python3.8/site-packages/telebot/__init__.py", line 691, in __threaded_polling
    raise e
  File "/home/tepes/PycharmProjects/testing_python/venv/lib/python3.8/site-packages/telebot/__init__.py", line 650, in __threaded_polling
    polling_thread.raise_exceptions()
  File "/home/tepes/PycharmProjects/testing_python/venv/lib/python3.8/site-packages/telebot/util.py", line 107, in raise_exceptions
    raise self.exception_info
  File "/home/tepes/PycharmProjects/testing_python/venv/lib/python3.8/site-packages/telebot/util.py", line 89, in run
    task(*args, **kwargs)
  File "/home/tepes/PycharmProjects/testing_python/venv/lib/python3.8/site-packages/telebot/__init__.py", line 371, in __retrieve_updates
    updates = self.get_updates(offset=(self.last_update_id + 1),
  File "/home/tepes/PycharmProjects/testing_python/venv/lib/python3.8/site-packages/telebot/__init__.py", line 349, in get_updates
    json_updates = apihelper.get_updates(self.token, offset, limit, timeout, allowed_updates, long_polling_timeout)
  File "/home/tepes/PycharmProjects/testing_python/venv/lib/python3.8/site-packages/telebot/apihelper.py", line 328, in get_updates
    return _make_request(token, method_url, params=payload)
  File "/home/tepes/PycharmProjects/testing_python/venv/lib/python3.8/site-packages/telebot/apihelper.py", line 152, in _make_request
    result = _get_req_session().request(
  File "/home/tepes/PycharmProjects/testing_python/venv/lib/python3.8/site-packages/requests/sessions.py", line 529, in request
    resp = self.send(prep, **send_kwargs)
  File "/home/tepes/PycharmProjects/testing_python/venv/lib/python3.8/site-packages/requests/sessions.py", line 645, in send
    r = adapter.send(request, **kwargs)
  File "/home/tepes/PycharmProjects/testing_python/venv/lib/python3.8/site-packages/requests/adapters.py", line 532, in send
    raise ReadTimeout(e, request=request)
requests.exceptions.ReadTimeout: HTTPSConnectionPool(host='api.telegram.org', port=443): Read timed out. (read timeout=25)

